<?xml version="1.0" ?>
<robot name="yumi">
  <link name="world"/>
  
  <joint name="base" type="fixed">
  	<parent link="world"/>
  	<child link="body"/>
  	<origin xyz="0 0 0" rpy="0 0 0"/>
  </joint>
  <joint name="joint_1R" type="revolute">
    <parent link="body"/>
    <child link="link_1R"/>
    <origin rpy="-0.9795 -0.5682 -2.3155" xyz="0.05355 -0.07249  0.51492"/>
    <axis xyz="0  0  1"/>
    <limit effort="300.0" lower="-2.9394" upper="2.9394" velocity="3.14"/>
    <dynamics damping="0.5"/>
  </joint>
  <joint name="joint_2R" type="revolute">
    <parent link="link_1R"/>
    <child link="link_2R"/>
    <origin rpy="1.5707  0      0" xyz="2.99600000e-02   3.00000000e-05   9.99800000e-02"/>
    <axis xyz="0  0  1"/>
    <limit effort="300.0" lower="-2.5033" upper="0.7588" velocity="3.14"/>
    <dynamics damping="0.5"/>
  </joint>
  <joint name="joint_7R" type="revolute">
    <parent link="link_2R"/>
    <child link="link_3R"/>
    <origin rpy="-1.5707  0      0" xyz="-3.00100000e-02   1.72850000e-01   6.00000000e-05"/>
    <axis xyz="0  0  1"/>
    <limit effort="300.0" lower="-2.9394" upper="2.9394" velocity="3.14"/>
    <dynamics damping="0.5"/>
  </joint>
  <joint name="joint_3R" type="revolute">
    <parent link="link_3R"/>
    <child link="link_4R"/>
    <origin rpy="1.5707  0      0" xyz="-4.18400000e-02  -1.00000000e-05   7.87600000e-02"/>
    <axis xyz="0  0  1"/>
    <limit effort="300.0" lower="-2.1544" upper="1.3956" velocity="3.14"/>
    <dynamics damping="0.5"/>
  </joint>
  <joint name="joint_4R" type="revolute">
    <parent link="link_4R"/>
    <child link="link_5R"/>
    <origin rpy="-1.5707  0      0" xyz="4.15700000e-02   1.64360000e-01   1.00000000e-05"/>
    <axis xyz="0  0  1"/>
    <limit effort="300.0" lower="-5.0589" upper="5.0589" velocity="6.98"/>
    <dynamics damping="0.5"/>
  </joint>
  <joint name="joint_5R" type="revolute">
    <parent link="link_5R"/>
    <child link="link_6R"/>
    <origin rpy="1.5707  0      0" xyz="-2.63800000e-02   6.00000000e-05   1.00550000e-01"/>
    <axis xyz="0  0  1"/>
    <limit effort="300.0" lower="-1.5351" upper="2.4073" velocity="6.98"/>
    <dynamics damping="0.5"/>
  </joint>
  <joint name="joint_6R" type="revolute">
    <parent link="link_6R"/>
    <child link="link_7R"/>
    <origin rpy="-1.5707  0      0" xyz="2.72000000e-02   2.88100000e-02   3.00000000e-05"/>
    <axis xyz="0  0  1"/>
    <limit effort="300.0" lower="-3.9948" upper="3.9948" velocity="3.14"/>
    <dynamics damping="0.5"/>
  </joint>
  <joint name="joint_1L" type="revolute">
    <parent link="body"/>
    <child link="link_1L"/>
    <origin rpy="0.9781 -0.5716  2.318" xyz="0.05355  0.07249  0.51492"/>
    <axis xyz="0  0  1"/>
    <limit effort="300.0" lower="-2.9394" upper="2.9394" velocity="3.14"/>
    <dynamics damping="0.5"/>
  </joint>
  <joint name="joint_2L" type="revolute">
    <parent link="link_1L"/>
    <child link="link_2L"/>
    <origin rpy="1.5707  0      0" xyz="0.02997 -0.00015  0.09998"/>
    <axis xyz="0  0  1"/>
    <limit effort="300.0" lower="-2.5033" upper="0.7588" velocity="3.14"/>
    <dynamics damping="0.5"/>
  </joint>
  <joint name="joint_7L" type="revolute">
    <parent link="link_2L"/>
    <child link="link_3L"/>
    <origin rpy="-1.5707  0      0" xyz="-2.99800000e-02   1.72850000e-01  -1.40000000e-04"/>
    <axis xyz="0  0  1"/>
    <limit effort="300.0" lower="-2.9394" upper="2.9394" velocity="3.14"/>
    <dynamics damping="0.5"/>
  </joint>
  <joint name="joint_3L" type="revolute">
    <parent link="link_3L"/>
    <child link="link_4L"/>
    <origin rpy="1.5707  0      0" xyz="-0.04183  0.00018  0.07877"/>
    <axis xyz="0  0  1"/>
    <limit effort="300.0" lower="-2.1544" upper="1.3956" velocity="3.14"/>
    <dynamics damping="0.5"/>
  </joint>
  <joint name="joint_4L" type="revolute">
    <parent link="link_4L"/>
    <child link="link_5L"/>
    <origin rpy="-1.5707  0      0" xyz="0.0416   0.16435  0.00019"/>
    <axis xyz="0  0  1"/>
    <limit effort="300.0" lower="-5.0589" upper="5.0589" velocity="6.98"/>
    <dynamics damping="0.5"/>
  </joint>
  <joint name="joint_5L" type="revolute">
    <parent link="link_5L"/>
    <child link="link_6L"/>
    <origin rpy="1.5707  0      0" xyz="-2.63600000e-02   3.00000000e-05   1.00550000e-01"/>
    <axis xyz="0  0  1"/>
    <limit effort="300.0" lower="-1.5351" upper="2.4073" velocity="6.98"/>
    <dynamics damping="0.5"/>
  </joint>
  <joint name="joint_6L" type="revolute">
    <parent link="link_6L"/>
    <child link="link_7L"/>
    <origin rpy="-1.5707  0      0" xyz="2.72100000e-02   2.88000000e-02   8.00000000e-05"/>
    <axis xyz="0  0  1"/>
    <limit effort="300.0" lower="-3.9948" upper="3.9948" velocity="3.14"/>
    <dynamics damping="0.5"/>
  </joint>
  <link name="body">
    <inertial>
      <mass value="15"/>
      <origin rpy="0  0  0" xyz="0   0   0.1"/>
      <inertia ixx="0.6" ixy="0" ixz="0" iyy="0.5" iyz="0" izz="0.3"/>
    </inertial>
    <collision name="collision">
      <origin rpy="0  0  0" xyz="0   0   0.1"/>
      <geometry>
        <mesh filename="package://yumi_description/meshes/coarse/body.stl" scale="1.0 1.0 1.0"/>
      </geometry>
    </collision>
    <visual name="test">
      <origin rpy="0  0  0" xyz="0   0   0.1"/>
      <geometry>
        <mesh filename="package://yumi_description/meshes/body.stl" scale="1.0 1.0 1.0"/>
      </geometry>
    </visual>
  </link>
  <link name="link_1R">
    <inertial>
      <mass value="1"/>
      <origin rpy="0  0  0" xyz="0  0  0"/>
      <inertia ixx="0.1" ixy="0" ixz="0" iyy="0.1" iyz="0" izz="0.1"/>
    </inertial>
    <collision name="collision">
      <origin rpy="0  0  0" xyz="0  0  0"/>
      <geometry>
        <mesh filename="package://yumi_description/meshes/coarse/link_1.stl" scale="1.0 1.0 1.0"/>
      </geometry>
    </collision>
    <visual name="link1">
      <origin rpy="0  0  0" xyz="0  0  0"/>
      <geometry>
        <mesh filename="package://yumi_description/meshes/link_1.stl" scale="1.0 1.0 1.0"/>
      </geometry>
    </visual>
  </link>
  <link name="link_2R">
    <inertial>
      <mass value="1"/>
      <origin rpy="0  0  0" xyz="0  0  0"/>
      <inertia ixx="0.1" ixy="0" ixz="0" iyy="0.1" iyz="0" izz="0.1"/>
    </inertial>
    <collision name="collision">
      <origin rpy="0  0  0" xyz="0  0  0"/>
      <geometry>
        <mesh filename="package://yumi_description/meshes/coarse/link_2.stl" scale="1.0 1.0 1.0"/>
      </geometry>
    </collision>
    <visual name="link2">
      <origin rpy="0  0  0" xyz="0  0  0"/>
      <geometry>
        <mesh filename="package://yumi_description/meshes/link_2.stl" scale="1.0 1.0 1.0"/>
      </geometry>
    </visual>
  </link>
  <link name="link_3R">
    <inertial>
      <mass value="1"/>
      <origin rpy="0  0  0" xyz="0  0  0"/>
      <inertia ixx="0.1" ixy="0" ixz="0" iyy="0.1" iyz="0" izz="0.1"/>
    </inertial>
    <collision name="collision">
      <origin rpy="0  0  0" xyz="0  0  0"/>
      <geometry>
        <mesh filename="package://yumi_description/meshes/coarse/link_3.stl" scale="1.0 1.0 1.0"/>
      </geometry>
    </collision>
    <visual name="link3">
      <origin rpy="0  0  0" xyz="0  0  0"/>
      <geometry>
        <mesh filename="package://yumi_description/meshes/link_3.stl" scale="1.0 1.0 1.0"/>
      </geometry>
    </visual>
  </link>
  <link name="link_4R">
    <inertial>
      <mass value="1"/>
      <origin rpy="0  0  0" xyz="0  0  0"/>
      <inertia ixx="0.1" ixy="0" ixz="0" iyy="0.1" iyz="0" izz="0.1"/>
    </inertial>
    <collision name="collision">
      <origin rpy="0  0  0" xyz="0  0  0"/>
      <geometry>
        <mesh filename="package://yumi_description/meshes/coarse/link_4.stl" scale="1.0 1.0 1.0"/>
      </geometry>
    </collision>
    <visual name="link4">
      <origin rpy="0  0  0" xyz="0  0  0"/>
      <geometry>
        <mesh filename="package://yumi_description/meshes/link_4.stl" scale="1.0 1.0 1.0"/>
      </geometry>
    </visual>
  </link>
  <link name="link_5R">
    <inertial>
      <mass value="1"/>
      <origin rpy="0  0  0" xyz="0  0  0"/>
      <inertia ixx="0.1" ixy="0" ixz="0" iyy="0.1" iyz="0" izz="0.1"/>
    </inertial>
    <collision name="collision">
      <origin rpy="0  0  0" xyz="0  0  0"/>
      <geometry>
        <mesh filename="package://yumi_description/meshes/coarse/link_5.stl" scale="1.0 1.0 1.0"/>
      </geometry>
    </collision>
    <visual name="link5">
      <origin rpy="0  0  0" xyz="0  0  0"/>
      <geometry>
        <mesh filename="package://yumi_description/meshes/link_5.stl" scale="1.0 1.0 1.0"/>
      </geometry>
    </visual>
  </link>
  <link name="link_6R">
    <inertial>
      <mass value="1"/>
      <origin rpy="0  0  0" xyz="0  0  0"/>
      <inertia ixx="0.1" ixy="0" ixz="0" iyy="0.1" iyz="0" izz="0.1"/>
    </inertial>
    <collision name="collision">
      <origin rpy="0  0  0" xyz="0  0  0"/>
      <geometry>
        <mesh filename="package://yumi_description/meshes/coarse/link_6.stl" scale="1.0 1.0 1.0"/>
      </geometry>
    </collision>
    <visual name="link5">
      <origin rpy="0  0  0" xyz="0  0  0"/>
      <geometry>
        <mesh filename="package://yumi_description/meshes/link_6.stl" scale="1.0 1.0 1.0"/>
      </geometry>
    </visual>
  </link>
  <link name="link_7R">
    <inertial>
      <mass value="1"/>
      <origin rpy="0  0  0" xyz="0  0  0"/>
      <inertia ixx="0.1" ixy="0" ixz="0" iyy="0.1" iyz="0" izz="0.1"/>
    </inertial>
    <collision name="collision">
      <origin rpy="0  0  0" xyz="0  0  0"/>
      <geometry>
        <mesh filename="package://yumi_description/meshes/coarse/link_7.stl" scale="1.0 1.0 1.0"/>
      </geometry>
    </collision>
    <visual name="link7">
      <origin rpy="0  0  0" xyz="0  0  0"/>
      <geometry>
        <mesh filename="package://yumi_description/meshes/link_7.stl" scale="1.0 1.0 1.0"/>
      </geometry>
    </visual>
  </link>
  <link name="link_1L">
    <inertial>
      <mass value="1"/>
      <origin rpy="0  0  0" xyz="0  0  0"/>
      <inertia ixx="0.1" ixy="0" ixz="0" iyy="0.1" iyz="0" izz="0.1"/>
    </inertial>
    <collision name="collision">
      <origin rpy="0  0  0" xyz="0  0  0"/>
      <geometry>
        <mesh filename="package://yumi_description/meshes/coarse/link_1.stl" scale="1.0 1.0 1.0"/>
      </geometry>
    </collision>
    <visual name="link1l">
      <origin rpy="0  0  0" xyz="0  0  0"/>
      <geometry>
        <mesh filename="package://yumi_description/meshes/link_1.stl" scale="1.0 1.0 1.0"/>
      </geometry>
    </visual>
  </link>
  <link name="link_2L">
    <inertial>
      <mass value="1"/>
      <origin rpy="0  0  0" xyz="0  0  0"/>
      <inertia ixx="0.1" ixy="0" ixz="0" iyy="0.1" iyz="0" izz="0.1"/>
    </inertial>
    <collision name="collision">
      <origin rpy="0  0  0" xyz="0  0  0"/>
      <geometry>
        <mesh filename="package://yumi_description/meshes/coarse/link_2.stl" scale="1.0 1.0 1.0"/>
      </geometry>
    </collision>
    <visual name="link2">
      <origin rpy="0  0  0" xyz="0  0  0"/>
      <geometry>
        <mesh filename="package://yumi_description/meshes/link_2.stl" scale="1.0 1.0 1.0"/>
      </geometry>
    </visual>
  </link>
  <link name="link_3L">
    <inertial>
      <mass value="1"/>
      <origin rpy="0  0  0" xyz="0  0  0"/>
      <inertia ixx="0.1" ixy="0" ixz="0" iyy="0.1" iyz="0" izz="0.1"/>
    </inertial>
    <collision name="collision">
      <origin rpy="0  0  0" xyz="0  0  0"/>
      <geometry>
        <mesh filename="package://yumi_description/meshes/coarse/link_3.stl" scale="1.0 1.0 1.0"/>
      </geometry>
    </collision>
    <visual name="link3">
      <origin rpy="0  0  0" xyz="0  0  0"/>
      <geometry>
        <mesh filename="package://yumi_description/meshes/link_3.stl" scale="1.0 1.0 1.0"/>
      </geometry>
    </visual>
  </link>
  <link name="link_4L">
    <inertial>
      <mass value="1"/>
      <origin rpy="0  0  0" xyz="0  0  0"/>
      <inertia ixx="0.1" ixy="0" ixz="0" iyy="0.1" iyz="0" izz="0.1"/>
    </inertial>
    <collision name="collision">
      <origin rpy="0  0  0" xyz="0  0  0"/>
      <geometry>
        <mesh filename="package://yumi_description/meshes/coarse/link_4.stl" scale="1.0 1.0 1.0"/>
      </geometry>
    </collision>
    <visual name="link4">
      <origin rpy="0  0  0" xyz="0  0  0"/>
      <geometry>
        <mesh filename="package://yumi_description/meshes/link_4.stl" scale="1.0 1.0 1.0"/>
      </geometry>
    </visual>
  </link>
  <link name="link_5L">
    <inertial>
      <mass value="1"/>
      <origin rpy="0  0  0" xyz="0  0  0"/>
      <inertia ixx="0.1" ixy="0" ixz="0" iyy="0.1" iyz="0" izz="0.1"/>
    </inertial>
    <collision name="collision">
      <origin rpy="0  0  0" xyz="0  0  0"/>
      <geometry>
        <mesh filename="package://yumi_description/meshes/coarse/link_5.stl" scale="1.0 1.0 1.0"/>
      </geometry>
    </collision>
    <visual name="link5">
      <origin rpy="0  0  0" xyz="0  0  0"/>
      <geometry>
        <mesh filename="package://yumi_description/meshes/link_5.stl" scale="1.0 1.0 1.0"/>
      </geometry>
    </visual>
  </link>
  <link name="link_6L">
    <inertial>
      <mass value="1"/>
      <origin rpy="0  0  0" xyz="0  0  0"/>
      <inertia ixx="0.1" ixy="0" ixz="0" iyy="0.1" iyz="0" izz="0.1"/>
    </inertial>
    <collision name="collision">
      <origin rpy="0  0  0" xyz="0  0  0"/>
      <geometry>
        <mesh filename="package://yumi_description/meshes/coarse/link_6.stl" scale="1.0 1.0 1.0"/>
      </geometry>
    </collision>
    <visual name="link5">
      <origin rpy="0  0  0" xyz="0  0  0"/>
      <geometry>
        <mesh filename="package://yumi_description/meshes/link_6.stl" scale="1.0 1.0 1.0"/>
      </geometry>
    </visual>
  </link>
  <link name="link_7L">
    <inertial>
      <mass value="1"/>
      <origin rpy="0  0  0" xyz="0  0  0"/>
      <inertia ixx="0.1" ixy="0" ixz="0" iyy="0.1" iyz="0" izz="0.1"/>
    </inertial>
    <collision name="collision">
      <origin rpy="0  0  0" xyz="0  0  0"/>
      <geometry>
        <mesh filename="package://yumi_description/meshes/coarse/link_7.stl" scale="1.0 1.0 1.0"/>
      </geometry>
    </collision>
    <visual name="link7">
      <origin rpy="0  0  0" xyz="0  0  0"/>
      <geometry>
        <mesh filename="package://yumi_description/meshes/link_7.stl" scale="1.0 1.0 1.0"/>
      </geometry>
    </visual>
  </link>
  
  <transmission name="tran_1R">
      <type>transmission_interface/SimpleTransmission</type>
      <joint name="joint_1R">
	<hardwareInterface>EffortJointInterface</hardwareInterface>
      </joint>
      <actuator name="motor_1R">
	<mechanicalReduction>1</mechanicalReduction>
	<hardwareInterface>EffortJointInterface</hardwareInterface>
      </actuator>
    </transmission>
    
    <transmission name="tran_2R">
      <type>transmission_interface/SimpleTransmission</type>
      <joint name="joint_2R">
	<hardwareInterface>EffortJointInterface</hardwareInterface>
      </joint>
      <actuator name="motor_2R">
	<mechanicalReduction>1</mechanicalReduction>
	<hardwareInterface>EffortJointInterface</hardwareInterface>
      </actuator>
    </transmission>
    
    <transmission name="tran_7R">
      <type>transmission_interface/SimpleTransmission</type>
      <joint name="joint_7R">
	<hardwareInterface>EffortJointInterface</hardwareInterface>
      </joint>
      <actuator name="motor_7R">
	<mechanicalReduction>1</mechanicalReduction>
	<hardwareInterface>EffortJointInterface</hardwareInterface>
      </actuator>
    </transmission>
    
    <transmission name="tran_3R">
      <type>transmission_interface/SimpleTransmission</type>
      <joint name="joint_3R">
	<hardwareInterface>EffortJointInterface</hardwareInterface>
      </joint>
      <actuator name="motor_3R">
	<mechanicalReduction>1</mechanicalReduction>
	<hardwareInterface>EffortJointInterface</hardwareInterface>
      </actuator>
    </transmission>
    
    <transmission name="tran_4R">
      <type>transmission_interface/SimpleTransmission</type>
      <joint name="joint_4R">
	<hardwareInterface>EffortJointInterface</hardwareInterface>
      </joint>
      <actuator name="motor_4R">
	<mechanicalReduction>1</mechanicalReduction>
	<hardwareInterface>EffortJointInterface</hardwareInterface>
      </actuator>
    </transmission>
    
    <transmission name="tran_5R">
      <type>transmission_interface/SimpleTransmission</type>
      <joint name="joint_5R">
	<hardwareInterface>EffortJointInterface</hardwareInterface>
      </joint>
      <actuator name="motor_5R">
	<mechanicalReduction>1</mechanicalReduction>
	<hardwareInterface>EffortJointInterface</hardwareInterface>
      </actuator>
    </transmission>
    
    <transmission name="tran_6R">
      <type>transmission_interface/SimpleTransmission</type>
      <joint name="joint_6R">
	<hardwareInterface>EffortJointInterface</hardwareInterface>
      </joint>
      <actuator name="motor_6R">
	<mechanicalReduction>1</mechanicalReduction>
	<hardwareInterface>EffortJointInterface</hardwareInterface>
      </actuator>
    </transmission>
    
    <transmission name="tran_1L">
      <type>transmission_interface/SimpleTransmission</type>
      <joint name="joint_1L">
	<hardwareInterface>EffortJointInterface</hardwareInterface>
      </joint>
      <actuator name="motor_1L">
	<mechanicalReduction>1</mechanicalReduction>
	<hardwareInterface>EffortJointInterface</hardwareInterface>
      </actuator>
    </transmission>
    
    <transmission name="tran_2L">
      <type>transmission_interface/SimpleTransmission</type>
      <joint name="joint_2L">
	<hardwareInterface>EffortJointInterface</hardwareInterface>
      </joint>
      <actuator name="motor_2L">
	<mechanicalReduction>1</mechanicalReduction>
	<hardwareInterface>EffortJointInterface</hardwareInterface>
      </actuator>
    </transmission>
    
    <transmission name="tran_7L">
      <type>transmission_interface/SimpleTransmission</type>
      <joint name="joint_7L">
	<hardwareInterface>EffortJointInterface</hardwareInterface>
      </joint>
      <actuator name="motor_7L">
	<mechanicalReduction>1</mechanicalReduction>
	<hardwareInterface>EffortJointInterface</hardwareInterface>
      </actuator>
    </transmission>
    
    <transmission name="tran_3L">
      <type>transmission_interface/SimpleTransmission</type>
      <joint name="joint_3L">
	<hardwareInterface>EffortJointInterface</hardwareInterface>
      </joint>
      <actuator name="motor_3L">
	<mechanicalReduction>1</mechanicalReduction>
	<hardwareInterface>EffortJointInterface</hardwareInterface>
      </actuator>
    </transmission>
    
    <transmission name="tran_4L">
      <type>transmission_interface/SimpleTransmission</type>
      <joint name="joint_4L">
	<hardwareInterface>EffortJointInterface</hardwareInterface>
      </joint>
      <actuator name="motor_4L">
	<mechanicalReduction>1</mechanicalReduction>
	<hardwareInterface>EffortJointInterface</hardwareInterface>
      </actuator>
    </transmission>
    
    <transmission name="tran_5L">
      <type>transmission_interface/SimpleTransmission</type>
      <joint name="joint_5L">
	<hardwareInterface>EffortJointInterface</hardwareInterface>
      </joint>
      <actuator name="motor_5L">
	<mechanicalReduction>1</mechanicalReduction>
	<hardwareInterface>EffortJointInterface</hardwareInterface>
      </actuator>
    </transmission>
    
    <transmission name="tran_6L">
      <type>transmission_interface/SimpleTransmission</type>
      <joint name="joint_6L">
	<hardwareInterface>EffortJointInterface</hardwareInterface>
      </joint>
      <actuator name="motor_6L">
	<mechanicalReduction>1</mechanicalReduction>
	<hardwareInterface>EffortJointInterface</hardwareInterface>
      </actuator>
    </transmission>
    
    <gazebo>
    	<plugin name="control" filename="libgazebo_ros_control.so">
    		<robotNamespace>/yumi</robotNamespace>
    		<robotSimType>gazebo_ros_control/DefaultRobotHWSim</robotSimType>
    	</plugin>
    </gazebo>
</robot>
